<?xml version="1.0" encoding="UTF-8"?>
<testng-results skipped="0" failed="1" total="1" passed="0">
  <reporter-output>
  </reporter-output>
  <suite name="Default suite" duration-ms="23952" started-at="2019-05-10T04:12:38Z" finished-at="2019-05-10T04:13:02Z">
    <groups>
    </groups>
    <test name="Default test" duration-ms="23952" started-at="2019-05-10T04:12:38Z" finished-at="2019-05-10T04:13:02Z">
      <class name="open_Browser.Take_Screen_Shot">
        <test-method status="FAIL" signature="take_screen_shot()[pri:0, instance:open_Browser.Take_Screen_Shot@737996a0]" name="take_screen_shot" duration-ms="21096" started-at="2019-05-09T21:12:38Z" finished-at="2019-05-09T21:12:59Z">
          <exception class="java.lang.AssertionError">
            <message>
              <![CDATA[expected [true] but found [false]]]>
            </message>
            <full-stacktrace>
              <![CDATA[java.lang.AssertionError: expected [true] but found [false]
	at org.testng.Assert.fail(Assert.java:94)
	at org.testng.Assert.failNotEquals(Assert.java:494)
	at org.testng.Assert.assertTrue(Assert.java:42)
	at org.testng.Assert.assertTrue(Assert.java:52)
	at open_Browser.Take_Screen_Shot.take_screen_shot(Take_Screen_Shot.java:38)
	at sun.reflect.NativeMethodAccessorImpl.invoke0(Native Method)
	at sun.reflect.NativeMethodAccessorImpl.invoke(Unknown Source)
	at sun.reflect.DelegatingMethodAccessorImpl.invoke(Unknown Source)
	at java.lang.reflect.Method.invoke(Unknown Source)
	at org.testng.internal.MethodInvocationHelper.invokeMethod(MethodInvocationHelper.java:84)
	at org.testng.internal.Invoker.invokeMethod(Invoker.java:714)
	at org.testng.internal.Invoker.invokeTestMethod(Invoker.java:901)
	at org.testng.internal.Invoker.invokeTestMethods(Invoker.java:1231)
	at org.testng.internal.TestMethodWorker.invokeTestMethods(TestMethodWorker.java:127)
	at org.testng.internal.TestMethodWorker.run(TestMethodWorker.java:111)
	at org.testng.TestRunner.privateRun(TestRunner.java:767)
	at org.testng.TestRunner.run(TestRunner.java:617)
	at org.testng.SuiteRunner.runTest(SuiteRunner.java:334)
	at org.testng.SuiteRunner.runSequentially(SuiteRunner.java:329)
	at org.testng.SuiteRunner.privateRun(SuiteRunner.java:291)
	at org.testng.SuiteRunner.run(SuiteRunner.java:240)
	at org.testng.SuiteRunnerWorker.runSuite(SuiteRunnerWorker.java:52)
	at org.testng.SuiteRunnerWorker.run(SuiteRunnerWorker.java:86)
	at org.testng.TestNG.runSuitesSequentially(TestNG.java:1224)
	at org.testng.TestNG.runSuitesLocally(TestNG.java:1149)
	at org.testng.TestNG.run(TestNG.java:1057)
	at org.testng.remote.AbstractRemoteTestNG.run(AbstractRemoteTestNG.java:115)
	at org.testng.remote.RemoteTestNG.initAndRun(RemoteTestNG.java:251)
	at org.testng.remote.RemoteTestNG.main(RemoteTestNG.java:77)
]]>
            </full-stacktrace>
          </exception> <!-- java.lang.AssertionError -->
          <reporter-output>
          </reporter-output>
        </test-method> <!-- take_screen_shot -->
        <test-method status="PASS" signature="after_Test_Activity(org.testng.ITestResult)[pri:0, instance:open_Browser.Take_Screen_Shot@737996a0]" name="after_Test_Activity" is-config="true" duration-ms="2832" started-at="2019-05-09T21:12:59Z" finished-at="2019-05-09T21:13:02Z">
          <params>
            <param index="0">
              <value>
                <![CDATA[[TestResult name=take_screen_shot status=FAILURE method=Take_Screen_Shot.take_screen_shot()[pri:0, instance:open_Browser.Take_Screen_Shot@737996a0] output={null}]]]>
              </value>
            </param>
          </params>
          <reporter-output>
          </reporter-output>
        </test-method> <!-- after_Test_Activity -->
      </class> <!-- open_Browser.Take_Screen_Shot -->
    </test> <!-- Default test -->
  </suite> <!-- Default suite -->
</testng-results>
